<?xml version="1.0" encoding="utf-8"?>
<!-- This URDF was automatically created by SolidWorks to URDF Exporter! Originally created by Stephen Brawner (brawner@gmail.com) 
     Commit Version: 1.6.0-4-g7f85cfe  Build Version: 1.6.7995.38578
     For more information, please see http://wiki.ros.org/sw_urdf_exporter -->
<robot
  name="urdf y gripper 2">
  <link
    name="base_link">
    <inertial>
      <origin
        xyz="0.0620154234110682 0.0287828530200332 0.0194399840557853"
        rpy="0 0 0" />
      <mass
        value="0.814654269422782" />
      <inertia
        ixx="0.00321225759807019"
        ixy="-5.94963872437992E-05"
        ixz="-4.09310030216226E-06"
        iyy="0.00681091711547534"
        iyz="1.70805052077515E-07"
        izz="0.00410985447956931" />
    </inertial>
    <visual>
      <origin
        xyz="0 0 0"
        rpy="0 0 0" />
      <geometry>
        <mesh
          filename="package://urdf y gripper 2/meshes/base_link.STL" />
      </geometry>
      <material
        name="">
        <color
          rgba="0.792156862745098 0.819607843137255 0.933333333333333 1" />
      </material>
    </visual>
    <collision>
      <origin
        xyz="0 0 0"
        rpy="0 0 0" />
      <geometry>
        <mesh
          filename="package://urdf y gripper 2/meshes/base_link.STL" />
      </geometry>
    </collision>
  </link>
  <link
    name="1">
    <inertial>
      <origin
        xyz="0.0194962567255034 0.0112262534519014 0.078113516182697"
        rpy="0 0 0" />
      <mass
        value="0.355121581213206" />
      <inertia
        ixx="0.00125603542570872"
        ixy="-0.000555249047729999"
        ixz="0.000259680747218291"
        iyy="0.00189659685842054"
        iyz="0.00015044977523268"
        izz="0.00165493757001617" />
    </inertial>
    <visual>
      <origin
        xyz="0 0 0"
        rpy="0 0 0" />
      <geometry>
        <mesh
          filename="package://urdf y gripper 2/meshes/1.STL" />
      </geometry>
      <material
        name="">
        <color
          rgba="0.792156862745098 0.819607843137255 0.933333333333333 1" />
      </material>
    </visual>
    <collision>
      <origin
        xyz="0 0 0"
        rpy="0 0 0" />
      <geometry>
        <mesh
          filename="package://urdf y gripper 2/meshes/1.STL" />
      </geometry>
    </collision>
  </link>
  <joint
    name="1"
    type="continuous">
    <origin
      xyz="0.0454347510074524 -0.0194924164116458 0.0427918681373972"
      rpy="0 0 -0.49557" />
    <parent
      link="base_link" />
    <child
      link="1" />
    <axis
      xyz="0 0 1" />
  </joint>
  <link
    name="2">
    <inertial>
      <origin
        xyz="0.0321790284208932 0.0387517372140779 0.129799464054696"
        rpy="0 0 0" />
      <mass
        value="0.514099608790563" />
      <inertia
        ixx="0.00180786464083964"
        ixy="7.74792552574944E-05"
        ixz="-0.000644830625298174"
        iyy="0.00201839346894238"
        iyz="3.95355749513025E-05"
        izz="0.000642833598924862" />
    </inertial>
    <visual>
      <origin
        xyz="0 0 0"
        rpy="0 0 0" />
      <geometry>
        <mesh
          filename="package://urdf y gripper 2/meshes/2.STL" />
      </geometry>
      <material
        name="">
        <color
          rgba="0.792156862745098 0.819607843137255 0.933333333333333 1" />
      </material>
    </visual>
    <collision>
      <origin
        xyz="0 0 0"
        rpy="0 0 0" />
      <geometry>
        <mesh
          filename="package://urdf y gripper 2/meshes/2.STL" />
      </geometry>
    </collision>
  </link>
  <joint
    name="2"
    type="continuous">
    <origin
      xyz="0 0 0.0930581318626029"
      rpy="1.5421939 -1.0470204 2.1191647" />
    <parent
      link="1" />
    <child
      link="2" />
    <axis
      xyz="0.500000000000001 -0.866025403784438 0" />
  </joint>
  <link
    name="3">
    <inertial>
      <origin
        xyz="0.160285451537985 0.0390539194758058 -0.0327831842575367"
        rpy="0 0 0" />
      <mass
        value="0.148274265947056" />
      <inertia
        ixx="5.33432313935929E-05"
        ixy="-3.05053739174086E-06"
        ixz="3.81633178561702E-05"
        iyy="0.00022552110386809"
        iyz="5.28312759383035E-07"
        izz="0.000231079216630846" />
    </inertial>
    <visual>
      <origin
        xyz="0 0 0"
        rpy="0 0 0" />
      <geometry>
        <mesh
          filename="package://urdf y gripper 2/meshes/3.STL" />
      </geometry>
      <material
        name="">
        <color
          rgba="0.792156862745098 0.819607843137255 0.933333333333333 1" />
      </material>
    </visual>
    <collision>
      <origin
        xyz="0 0 0"
        rpy="0 0 0" />
      <geometry>
        <mesh
          filename="package://urdf y gripper 2/meshes/3.STL" />
      </geometry>
    </collision>
  </link>
  <joint
    name="3"
    type="continuous">
    <origin
      xyz="0.118562532535808 0.0684521100753529 0.37687220459222"
      rpy="0 1.150442 0.523599" />
    <parent
      link="2" />
    <child
      link="3" />
    <axis
      xyz="0 -1 0" />
  </joint>
  <link
    name="4">
    <inertial>
      <origin
        xyz="-0.00934416150525474 -0.000677982540279336 -0.0368117366199101"
        rpy="0 0 0" />
      <mass
        value="0.0891556215531032" />
      <inertia
        ixx="2.88078312181138E-05"
        ixy="-1.19720534200001E-06"
        ixz="1.29339806412181E-06"
        iyy="2.97059325514424E-05"
        iyz="4.77175311125223E-07"
        izz="3.32395106205033E-05" />
    </inertial>
    <visual>
      <origin
        xyz="0 0 0"
        rpy="0 0 0" />
      <geometry>
        <mesh
          filename="package://urdf y gripper 2/meshes/4.STL" />
      </geometry>
      <material
        name="">
        <color
          rgba="0.792156862745098 0.819607843137255 0.933333333333333 1" />
      </material>
    </visual>
    <collision>
      <origin
        xyz="0 0 0"
        rpy="0 0 0" />
      <geometry>
        <mesh
          filename="package://urdf y gripper 2/meshes/4.STL" />
      </geometry>
    </collision>
  </link>
  <joint
    name="4"
    type="continuous">
    <origin
      xyz="0.23364964353366 0 -0.04785492740141"
      rpy="0 -0.359292 0" />
    <parent
      link="3" />
    <child
      link="4" />
    <axis
      xyz="0 -1 0" />
  </joint>
  <link
    name="left_link">
    <inertial>
      <origin
        xyz="-0.000469947739044435 0.0174936888369082 0.00300000000000089"
        rpy="0 0 0" />
      <mass
        value="0.00336762222486258" />
      <inertia
        ixx="6.2747061339946E-07"
        ixy="1.55947433705602E-08"
        ixz="-8.41656273272706E-23"
        iyy="4.73790672083762E-08"
        iyz="1.31305874954843E-21"
        izz="6.18722643526794E-07" />
    </inertial>
    <visual>
      <origin
        xyz="0 0 0"
        rpy="0 0 0" />
      <geometry>
        <mesh
          filename="package://urdf y gripper 2/meshes/left_link.STL" />
      </geometry>
      <material
        name="">
        <color
          rgba="0.792156862745098 0.819607843137255 0.933333333333333 1" />
      </material>
    </visual>
    <collision>
      <origin
        xyz="0 0 0"
        rpy="0 0 0" />
      <geometry>
        <mesh
          filename="package://urdf y gripper 2/meshes/left_link.STL" />
      </geometry>
    </collision>
  </link>
  <joint
    name="left_joint"
    type="continuous">
    <origin
      xyz="-0.0446374847636057 0 -0.0675895135948699"
      rpy="-0.636182262047826 -0.816033703582543 0.792345504410718" />
    <parent
      link="4" />
    <child
      link="left_link" />
    <axis
      xyz="0 0 1" />
  </joint>
  <link
    name="right_link">
    <inertial>
      <origin
        xyz="0 -0.0175 -0.00300000000000045"
        rpy="0 0 0" />
      <mass
        value="0.00336762222486258" />
      <inertia
        ixx="6.27889548162521E-07"
        ixy="-2.87858853168454E-22"
        ixz="1.94387443949962E-23"
        iyy="4.6960132445314E-08"
        iyz="3.36838931424103E-21"
        izz="6.18722643526793E-07" />
    </inertial>
    <visual>
      <origin
        xyz="0 0 0"
        rpy="0 0 0" />
      <geometry>
        <mesh
          filename="package://urdf y gripper 2/meshes/right_link.STL" />
      </geometry>
      <material
        name="">
        <color
          rgba="0.792156862745098 0.819607843137255 0.933333333333333 1" />
      </material>
    </visual>
    <collision>
      <origin
        xyz="0 0 0"
        rpy="0 0 0" />
      <geometry>
        <mesh
          filename="package://urdf y gripper 2/meshes/right_link.STL" />
      </geometry>
    </collision>
  </link>
  <joint
    name="right_joint"
    type="continuous">
    <origin
      xyz="-0.0446374847636117 -0.01199999999993 -0.0675895135948783"
      rpy="2.48504023556058 0.801364458791681 2.32108947717299" />
    <parent
      link="4" />
    <child
      link="right_link" />
    <axis
      xyz="0 0 1" />
  </joint>
  <link
    name="left_gear">
    <inertial>
      <origin
        xyz="0.00332043434216367 5.55111512312578E-17 -0.00283964882726565"
        rpy="0 0 0" />
      <mass
        value="0.0208170455983243" />
      <inertia
        ixx="4.74146880578325E-06"
        ixy="-7.1848908006356E-21"
        ixz="-1.89418670297648E-08"
        iyy="3.75851791717855E-06"
        iyz="-2.32934060494933E-21"
        izz="2.19540725542139E-06" />
    </inertial>
    <visual>
      <origin
        xyz="0 0 0"
        rpy="0 0 0" />
      <geometry>
        <mesh
          filename="package://urdf y gripper 2/meshes/left_gear.STL" />
      </geometry>
      <material
        name="">
        <color
          rgba="1 0.949019607843137 0.909803921568627 1" />
      </material>
    </visual>
    <collision>
      <origin
        xyz="0 0 0"
        rpy="0 0 0" />
      <geometry>
        <mesh
          filename="package://urdf y gripper 2/meshes/left_gear.STL" />
      </geometry>
    </collision>
  </link>
  <joint
    name="left_gear"
    type="continuous">
    <origin
      xyz="-0.030860842200278 0.0120000000000486 -0.0467290960611094"
      rpy="-1.03436663934795 -0.583665698554612 3.14159265358977" />
    <parent
      link="4" />
    <child
      link="left_gear" />
    <axis
      xyz="1 0 0" />
  </joint>
  <link
    name="left_finger">
    <inertial>
      <origin
        xyz="0.00767435115108214 0.0771367226814144 0.0150000017340822"
        rpy="0 0 0" />
      <mass
        value="0.00826543782946823" />
      <inertia
        ixx="8.37291786945403E-06"
        ixy="-5.42084443454308E-07"
        ixz="-5.04273014281664E-15"
        iyy="6.05144732599242E-07"
        iyz="-2.60044833018136E-13"
        izz="8.06912919160269E-06" />
    </inertial>
    <visual>
      <origin
        xyz="0 0 0"
        rpy="0 0 0" />
      <geometry>
        <mesh
          filename="package://urdf y gripper 2/meshes/left_finger.STL" />
      </geometry>
      <material
        name="">
        <color
          rgba="0.792156862745098 0.819607843137255 0.933333333333333 1" />
      </material>
    </visual>
    <collision>
      <origin
        xyz="0 0 0"
        rpy="0 0 0" />
      <geometry>
        <mesh
          filename="package://urdf y gripper 2/meshes/left_finger.STL" />
      </geometry>
    </collision>
  </link>
  <joint
    name="left_finger_joint"
    type="fixed">
    <origin
      xyz="0.0180000000000023 -0.0295926571259712 -0.0163111090691601"
      rpy="-1.57079632679489 -1.03436663934697 1.57079632679489" />
    <parent
      link="left_gear" />
    <child
      link="left_finger" />
    <axis
      xyz="0 0 0" />
  </joint>
  <link
    name="right_gear">
    <inertial>
      <origin
        xyz="-0.00299999999999589 0.000235018102434981 -0.00268626920292762"
        rpy="0 0 0" />
      <mass
        value="0.0220238578526574" />
      <inertia
        ixx="4.81786570325033E-06"
        ixy="1.42440501481631E-21"
        ixz="3.75746793252213E-22"
        iyy="3.86576031906348E-06"
        iyz="1.3674437762972E-07"
        izz="2.31472851349093E-06" />
    </inertial>
    <visual>
      <origin
        xyz="0 0 0"
        rpy="0 0 0" />
      <geometry>
        <mesh
          filename="package://urdf y gripper 2/meshes/right_gear.STL" />
      </geometry>
      <material
        name="">
        <color
          rgba="1 0.949019607843137 0.909803921568627 1" />
      </material>
    </visual>
    <collision>
      <origin
        xyz="0 0 0"
        rpy="0 0 0" />
      <geometry>
        <mesh
          filename="package://urdf y gripper 2/meshes/right_gear.STL" />
      </geometry>
    </collision>
  </link>
  <joint
    name="right_gear_joint"
    type="continuous">
    <origin
      xyz="-0.0308608422002956 -0.0239999999999514 -0.0467290960611348"
      rpy="-1.1241367549404 0.583665698554614 0" />
    <parent
      link="4" />
    <child
      link="right_gear" />
    <axis
      xyz="1 0 0" />
  </joint>
  <link
    name="right_finger">
    <inertial>
      <origin
        xyz="0.00861288758144949 0.0421496228519228 1.90673787869855E-09"
        rpy="0 0 0" />
      <mass
        value="0.00826543786698466" />
      <inertia
        ixx="8.37295282843617E-06"
        ixy="-5.41833954768233E-07"
        ixz="7.35144046165134E-14"
        iyy="6.05109773246728E-07"
        iyz="-6.04862742966393E-14"
        izz="8.06912919102798E-06" />
    </inertial>
    <visual>
      <origin
        xyz="0 0 0"
        rpy="0 0 0" />
      <geometry>
        <mesh
          filename="package://urdf y gripper 2/meshes/right_finger.STL" />
      </geometry>
      <material
        name="">
        <color
          rgba="0.792156862745098 0.819607843137255 0.933333333333333 1" />
      </material>
    </visual>
    <collision>
      <origin
        xyz="0 0 0"
        rpy="0 0 0" />
      <geometry>
        <mesh
          filename="package://urdf y gripper 2/meshes/right_finger.STL" />
      </geometry>
    </collision>
  </link>
  <joint
    name="right_finger_joint"
    type="fixed">
    <origin
      xyz="-0.00300000000000089 0.00305045099616832 -0.0348668144332111"
      rpy="-1.57079580129379 -1.12416900857782 1.5707957933053" />
    <parent
      link="right_gear" />
    <child
      link="right_finger" />
    <axis
      xyz="0 0 0" />
  </joint>
</robot>